<?xml version="1.0"?>
<robot name="my_bot" xmlns:xacro="http://www.ros.org/wiki/xacro">
    
    <xacro:include filename="gazebo_control.xacro"/>
    <!--<xacro:include filename="inertial_macros.xacro"/>-->
    <xacro:include filename="lidar.xacro"/>
    <xacro:include filename="camera.xacro"/>
    <material name="white">
        <color rgba="1 1 1 1" />
    </material>

    <material name="orange">
        <color rgba="1 0.3 0.1 1" />
    </material>

    <material name="blue">
        <color rgba="0.2 0.2 1 1" />
    </material>

    <material name="black">
        <color rgba="0 0 0 1" />
    </material>

      <material name="red">
        <color rgba="1 0 0 1" />
    </material>

    <!-- base_link -->
    <link name="base_link">
    </link>
<!-- base_footprint_joint -->
    <joint name="base_footprint_joint" type="fixed">
        <parent link="base_link"/>
        <child link="base_footprint"/>
        <origin xyz="0 0 0" rpy="0 0 0" />
    </joint>

    <link name="base_footprint">
    </link>

    <!-- chassis -->
    <joint name="chassis_joint" type="fixed">
        <parent link="base_link"/>
        <child link="chassis"/>
        <origin xyz="-0.1 0 0"/>
    </joint>

    <link name="chassis">
        <visual>
            <origin xyz="0.15 0 0.075"/>
            <geometry>
                <box size="0.3 0.3 0.15"/>
            </geometry>
            <material name="white"/>
        </visual>

        <collision>
            <origin xyz="0.15 0 0.075"/>
            <geometry>
                <box size="0.3 0.3 0.15"/>
            </geometry>
        </collision>
        <inertial>
            <origin xyz="0.15 0.0 0.75" rpy="0.0 0.0 0.0"/>
            <mass value="3"/>
            <inertia ixx="${(1/12) * .5 * (0+.75*.75)}" ixy="0.0" ixz="0.0"
                    iyy="${(1/12) * .5 * (.15*.15+.75*.75)}" iyz="0.0"
                    izz="${(1/12) * .5 * (.15*.15+0)}" />
        </inertial>
        <!--<xacro:inertial_box mass="0.5" x=".03" y=".03" z=".15"/>
        <origin xyz="0.15 0 0.075" rpy="0 0 0"/>
        </xacro:inertial_box>-->
    </link>
    <gazebo reference="chassis">
    <material>Gazebo/White</material>
    </gazebo>
            
        

    <!-- left_wheel -->
    <joint name="left_wheel_joint" type="continuous">
        <parent link="base_link"/>
        <child link="left_wheel"/>
        <origin xyz="0 0.175 0" rpy="${-pi/2} 0 0"/>
        <axis xyz="0 0 1"/>
        
    </joint>

    <link name="left_wheel">
        <visual>
            <geometry>
                <cylinder radius="0.05" length="0.04"/>
            </geometry>
            <material name="blue"/>
        </visual>

        <collision>
            <geometry>
                <cylinder radius="0.05" length="0.04"/>
            </geometry>
        </collision>
        <inertial>
            <origin xyz="0.0 0.0 0.0" rpy="0.0 0.0 0.0"/>
            <mass value="0.1"/>
            <inertia ixx="${(1/12) * .1 * (3*0.05*0.05 + 0.04*0.04)}" ixy="0.0" ixz="0.0"
                    iyy="${(1/12) * .1 * (3*0.05*0.05 + 0.04*0.04)}" iyz="0.0"
                    izz="${(1/2) * .1 * (0.05*0.05)}" />
        </inertial>
        <!--xacro:inertial_cylinder mass="0.1" length=".03" radius=".05"/>
        <origin xyz="0 0 0" rpy="0 0 0"/>
        </xacro:inertial_cylinder>-->
    </link>
    <gazebo reference ="left_wheel">
        <material>gazebo/blue</material>
    </gazebo>
    <!-- right_wheel -->
    <joint name="right_wheel_joint" type="continuous">
        <parent link="base_link"/>
        <child link="right_wheel"/>
        <origin xyz="0 -0.175 0" rpy="${pi/2} 0 0"/>
        <axis xyz="0 0 -1"/>
        
    </joint>

    <link name="right_wheel">
        <visual>
            <geometry>
                <cylinder radius="0.05" length="0.04"/>
            </geometry>
            <material name="blue"/>
        </visual>

        <collision>
            <geometry>
                <cylinder radius="0.05" length="0.04"/>
            </geometry>
        </collision>
        <inertial>
            <origin xyz="0.0 0.0 0.0" rpy="0.0 0.0 0.0"/>
            <mass value="0.1"/>
            <inertia ixx="${(1/12) * .1 * (3*0.05*0.05 + 0.04*0.04)}" ixy="0.0" ixz="0.0"
                    iyy="${(1/12) * .1 * (3*0.05*0.05 + 0.04*0.04)}" iyz="0.0"
                    izz="${(1/2) * .1 * (0.05*0.05)}" />
        </inertial>
        <!--<xacro:inertial_cylinder mass="0.1" length=".03" radius=".05"/>
        <origin xyz="0 0 0" rpy="0 0 0"/>
        </xacro:inertial_cylinder>-->
    </link>
    <gazebo reference ="right_wheel">
        <material>gazebo/blue</material>
    </gazebo>
    <!-- caster_wheel -->
    <joint name="caster_wheel" type="fixed">
        <parent link="base_link"/>
        <child link="caster_wheel"/>
        <origin xyz="0.15 0 0" />
        <axis xyz="0 0 0"/>   
    </joint>

    <link name="caster_wheel">
        <visual>
            <geometry>
                <sphere radius="0.05" />
            </geometry>
            <material name="black"/>
        </visual>

        <collision>
            <geometry>
                <sphere radius="0.05" />
            </geometry>
        </collision>
        <inertial>
            <origin xyz="0.0 0.0 0.0" rpy="0.0 0.0 0.0"/>
            <mass value="0.1"/>
            <inertia ixx="${(2/5) * 0.1 * (0.05*0.05)}" ixy="0.0" ixz="0.0"
                    iyy="${(2/5) * 0.1 * (0.05*0.05)}" iyz="0.0"
                    izz="${(2/5) * 0.1 * (0.05*0.05)}" />
        </inertial>
        <!--<xacro:inertial_sphere mass="0.1"  radius=".05"/>
        <origin xyz="0 0 0" rpy="0 0 0"/>-->
    
    </link>
    <gazebo reference ="caster_wheel">
        <material>gazebo/black</material>
        <mu1 value="0.001"/>
        <mu2 value="0.001"/>
    </gazebo>
</robot>



